# Extracted from https://stackoverflow.com/questions/23337471/how-to-properly-assert-that-an-exception-gets-raised-in-pytest
pytest.fail(exc, pytrace=True) # before
pytest.fail(exc) # after

